Workbook

Sheet CONFIGURACION
A1: EXPORT HARET · CONFIGURACIÓN DE PRECIOS · Mayo 2026
A2: Celdas en amarillo = inputs manuales · Resto se calcula automáticamente
A4: A PARÁMETROS GENERALES | L4: Resumen de precio que se suma al precio de las mercancias
B5: Costo de la caja | C5: 1 | D5: USD / caja | L5: 2,5 * 160 | M5: 0.55
B6: Merma (%) | C6: 0.01 | L6: 2 * 160 | M6: 0.7
B7: DUE — costo fijo por envío | C7: 280 | D7: USD / envío | E7: Documento Único de Exportación — se distribuye entre las cajas del envío | L7: 2,5 * 180 | M7: 0.5
B8: Peso pallet + plástico | C8: =27+2.9 -> 29.9 | D8: kg / pallet | L8: 120 * 3 | M8: 0.5
B9: Tara de la caja vacía | C9: 0.4 | D9: kg / caja | L9: 120 * 4 | M9: 0.4
B10: ℹ Flete/caja = Tarifa × (kg neto + tara + peso pallet ÷ cajas/pallet) | DUE/caja = DUE ÷ (n° pallets × cajas/pallet)
A11: EUR / USD — TIPO DE CAMBIO (STOCKHISTORY: función nativa Excel 365, datos en tiempo real)
B12: 1 EUR = ? USD | C12: =IFERROR(INDEX(_xlfn.STOCKHISTORY("EUR/USD",TODAY(),TODAY(),0,0,1),1,1),C13) -> 1.164 | D12: USD | E12: ← STOCKHISTORY (tiempo real). Si falla usa valor de C13
B13: Valor manual (si STOCKHISTORY falla) | C13: 1.164 | D13: USD | E13: ← Editar cuando no haya conexión o Excel sin 365
B14: 1 USD = ? EUR (reverso automático) | C14: =1/C12 -> 0.85910653 | D14: EUR | E14: ← Automático = 1 ÷ C12
B15: ⚠ STOCKHISTORY requiere Excel 365. Si aparece #¿NOMBRE? → escriba la tasa en C13 (amarillo) y C12 usará ese valor.
A17: B TARIFAS CARGUERA — USD / kg aéreo
B18: DESTINO | C18: TARIFA USD/kg | E18: Nota | G18: 46161
B19: Madrid/España | C19: 2.35 | E19: ← tarifa mayo 2026 | G19: 2.25
B20: París/Francia | C20: 2.85 | G20: 2.75
B21: Londres/UK | C21: 2.6
B22: Suiza | C22: 2.6
B23: Países Bajos | C23: 2.75 | G23: 2.6
B24: Dubai/EAU | C24: 4.3 | G24: 4.3
B25: Berlín/Alemania | C25: 2.85
B26: Miami/USA | C26: 1.15
B27: (otros) | C27: 2.1
A30: C CAJAS POR PALLET (la carguera cobra peso bruto = kg neto + tara + pallet)
B31: GRUPO | C31: Cajas/Pallet | D31: Sobrepeso/caja kg | E31: Productos del grupo
B32: Grupo A | C32: 160 | D32: =$C$9+$C$8/C32 -> 0.586875 | E32: Granadilla
B33: Grupo B | C33: 180 | D33: =$C$9+$C$8/C33 -> 0.56611111 | E33: Pitahaya Amarilla
B34: Grupo C | C34: 160 | D34: =$C$9+$C$8/C34 -> 0.586875 | E34: Lulo · Maracuyá · Tomate · Taxo · Melon dulce
B35: Grupo D | C35: 120 | D35: =$C$9+$C$8/C35 -> 0.64916667 | E35: Cacao · Babaco
B36: Grupo E | C36: 160 | D36: =$C$9+$C$8/C36 -> 0.586875 | E36: Guanabana · Aguacate · Baby banano · Zapote
B37: Grupo F | C37: 120 | D37: =$C$9+$C$8/C37 -> 0.64916667 | E37: Roja P · Blanca P
B38: Grupo G | C38: 160 | D38: =$C$9+$C$8/C38 -> 0.586875 | E38: Physalis sin cáscara
B39: Grupo H | C39: 160 | D39: =$C$9+$C$8/C39 -> 0.586875 | E39: Physalis con cáscara
A41: D DESGLOSE DUE / CAJA — A más pallets, menor DUE por caja
B42: Grupo | C42: Cajas /Pallet | D42: 1 Pallet | E42: 2 Pallets | F42: 3 Pallets | G42: 4 Pallets | H42: 5 Pallets | I42: 6 Pallets | J42: 7 Pallets | K42: 8 Pallets | L42: 9 Pallets | M42: 10 Pallets | N42: 11 Pallets | O42: 12 Pallets | P42: 13 Pallets | Q42: 14 Pallets | R42: 15 Pallets | S42: 16 Pallets | T42: 17 Pallets | U42: 18 Pallets | V42: 19 Pallets | W42: 20 Pallets | X42: 21 Pallets | Y42: 22 Pallets | Z42: 23 Pallets
B43: Grupo A — Granadilla | C43: =C32 -> 160 | D43: =$C$7/(1*C32) -> 1.75 | E43: =$C$7/(2*C32) -> 0.875 | F43: =$C$7/(3*C32) -> 0.58333333 | G43: =$C$7/(4*C32) -> 0.4375 | H43: =$C$7/(5*C32) -> 0.35 | I43: =$C$7/(6*C32) -> 0.29166667 | J43: =$C$7/(7*C32) -> 0.25 | K43: =$C$7/(8*C32) -> 0.21875 | L43: =$C$7/(9*C32) -> 0.19444444 | M43: =$C$7/(10*C32) -> 0.175 | N43: =$C$7/(11*C32) -> 0.15909091 | O43: =$C$7/(12*C32) -> 0.14583333 | P43: =$C$7/(13*C32) -> 0.13461538 | Q43: =$C$7/(14*C32) -> 0.125 | R43: =$C$7/(15*C32) -> 0.11666667 | S43: =$C$7/(16*C32) -> 0.109375 | T43: =$C$7/(17*C32) -> 0.10294118 | U43: =$C$7/(18*C32) -> 0.097222222 | V43: =$C$7/(19*C32) -> 0.092105263 | W43: =$C$7/(20*C32) -> 0.0875 | X43: =$C$7/(21*C32) -> 0.083333333 | Y43: =$C$7/(22*C32) -> 0.079545455 | Z43: =$C$7/(23*C32) -> 0.076086957
B44: Grupo B — Pitahaya Amarilla | C44: =C33 -> 180 | D44: =$C$7/(1*C33) -> 1.5555556 | E44: =$C$7/(2*C33) -> 0.77777778 | F44: =$C$7/(3*C33) -> 0.51851852 | G44: =$C$7/(4*C33) -> 0.38888889 | H44: =$C$7/(5*C33) -> 0.31111111 | I44: =$C$7/(6*C33) -> 0.25925926 | J44: =$C$7/(7*C33) -> 0.22222222 | K44: =$C$7/(8*C33) -> 0.19444444 | L44: =$C$7/(9*C33) -> 0.17283951 | M44: =$C$7/(10*C33) -> 0.15555556 | N44: =$C$7/(11*C33) -> 0.14141414 | O44: =$C$7/(12*C33) -> 0.12962963 | P44: =$C$7/(13*C33) -> 0.11965812 | Q44: =$C$7/(14*C33) -> 0.11111111 | R44: =$C$7/(15*C33) -> 0.1037037 | S44: =$C$7/(16*C33) -> 0.097222222 | T44: =$C$7/(17*C33) -> 0.091503268 | U44: =$C$7/(18*C33) -> 0.086419753 | V44: =$C$7/(19*C33) -> 0.081871345 | W44: =$C$7/(20*C33) -> 0.077777778 | X44: =$C$7/(21*C33) -> 0.074074074 | Y44: =$C$7/(22*C33) -> 0.070707071 | Z44: =$C$7/(23*C33) -> 0.06763285
B45: Grupo C — Lulo · Maracuyá · Tomate · T | C45: =C34 -> 160 | D45: =$C$7/(1*C34) -> 1.75 | E45: =$C$7/(2*C34) -> 0.875 | F45: =$C$7/(3*C34) -> 0.58333333 | G45: =$C$7/(4*C34) -> 0.4375 | H45: =$C$7/(5*C34) -> 0.35 | I45: =$C$7/(6*C34) -> 0.29166667 | J45: =$C$7/(7*C34) -> 0.25 | K45: =$C$7/(8*C34) -> 0.21875 | L45: =$C$7/(9*C34) -> 0.19444444 | M45: =$C$7/(10*C34) -> 0.175 | N45: =$C$7/(11*C34) -> 0.15909091 | O45: =$C$7/(12*C34) -> 0.14583333 | P45: =$C$7/(13*C34) -> 0.13461538 | Q45: =$C$7/(14*C34) -> 0.125 | R45: =$C$7/(15*C34) -> 0.11666667 | S45: =$C$7/(16*C34) -> 0.109375 | T45: =$C$7/(17*C34) -> 0.10294118 | U45: =$C$7/(18*C34) -> 0.097222222 | V45: =$C$7/(19*C34) -> 0.092105263 | W45: =$C$7/(20*C34) -> 0.0875 | X45: =$C$7/(21*C34) -> 0.083333333 | Y45: =$C$7/(22*C34) -> 0.079545455 | Z45: =$C$7/(23*C34) -> 0.076086957
...

Sheet TABLA PRECIOS
A1: EXPORT HARET · TABLA DE PRECIOS · VIGENTE DESDE 12/05/2026
A2: Precios USD/caja · Pallets incluyen DUE distribuido · EUR = USD ÷ tipo de cambio BCE
B4: DESTINO: | C4: Madrid/España | E4: =INDEX(CONFIGURACION!$C$19:$C$27,MATCH(C4,CONFIGURACION!$B$19:$B$27,0)) -> 2.35 | G4: TIPO CAMBIO: | H4: =CONFIGURACION!$C$12 -> 1.164 | I4: ⇄ | J4: =1/CONFIGURACION!$C$12 -> 0.85910653 | K4: ← BCE / manual
B6: Código | C6: Producto | D6: Kg caja | E6: Precio compra | F6: Costo caja | G6: FOB base | H6: Merma | I6: FOB+ Merma | J6: Margen % | K6: Margen $ | L6: Precio FOB Final | M6: Flete $/caja | N6: CIF USD | O6: CIF $/kg | P6: USD 1 Pal | Q6: USD 2 Pal | R6: USD 3 Pal | S6: USD 4 Pal | T6: USD 5 Pal | U6: USD 6 Pal | V6: USD 7 Pal | W6: USD 8 Pal | X6: USD 9 Pal | Y6: USD 10 Pal | Z6: USD 11 Pal | AA6: USD 12 Pal | AB6: USD 13 Pal | AC6: USD 14 Pal | AD6: USD 15 Pal | AE6: USD 16 Pal | AF6: USD 17 Pal | AG6: USD 18 Pal | AH6: USD 19 Pal | AI6: USD 20 Pal | AJ6: USD 21 Pal | AK6: USD 22 Pal | AL6: USD 23 Pal
B7: F-PSG10 | C7: Granadilla | D7: 2 | E7: =IFERROR(LOOKUP(9.99E+307,D$32:D$83),19.19) -> 7.95 | F7: 0.03 | G7: =E7+F7 -> 7.98 | H7: =G7/(1-CONFIGURACION!$C$6)-G7 -> 0.080606061 | I7: =G7+H7 -> 8.0606061 | J7: 0.1 | K7: =I7/(1-J7)-I7 -> 0.8956229 | L7: =I7+K7 -> 8.956229 | M7: =E4*(D7+CONFIGURACION!$D$32) -> 6.0791563 | N7: =L7+M7 -> 15.035385 | O7: =N7/D7 -> 7.5176926 | P7: =N7+CONFIGURACION!$D$43+CONFIGURACION!$D$57 -> 17.160385 | Q7: =N7+CONFIGURACION!$E$43+CONFIGURACION!$E$57 -> 16.097885 | R7: =N7+CONFIGURACION!$F$43-CONFIGURACION!$F$57 -> 15.493719 | S7: =N7+CONFIGURACION!$G$43-CONFIGURACION!$G$57 -> 15.379135 | T7: =N7+CONFIGURACION!$H$43-CONFIGURACION!$H$57 -> 15.310385 | U7: =N7+CONFIGURACION!$I$43-CONFIGURACION!$I$57 -> 15.264552 | V7: =N7+CONFIGURACION!$J$43-CONFIGURACION!$J$57 -> 15.231814 | W7: =N7+CONFIGURACION!$K$43-CONFIGURACION!$K$57 -> 15.20726 | X7: =N7+CONFIGURACION!$L$43-CONFIGURACION!$L$57 -> 15.188163 | Y7: =N7+CONFIGURACION!$M$43-CONFIGURACION!$M$57 -> 15.172885 | Z7: =N7+CONFIGURACION!$N$43-CONFIGURACION!$N$57 -> 15.160385 | AA7: =N7+CONFIGURACION!$O$43-CONFIGURACION!$O$57 -> 15.149969 | AB7: =N7+CONFIGURACION!$P$43-CONFIGURACION!$P$57 -> 15.141154 | AC7: =N7+CONFIGURACION!$Q$43-CONFIGURACION!$Q$57 -> 15.133599 | AD7: =N7+CONFIGURACION!$R$43-CONFIGURACION!$R$57 -> 15.127052 | AE7: =N7+CONFIGURACION!$S$43-CONFIGURACION!$S$57 -> 15.121323 | AF7: =N7+CONFIGURACION!$T$43-CONFIGURACION!$T$57 -> 15.116268 | AG7: =N7+CONFIGURACION!$U$43-CONFIGURACION!$U$57 -> 15.111774 | AH7: =N7+CONFIGURACION!$V$43-CONFIGURACION!$V$57 -> 15.107754 | AI7: =N7+CONFIGURACION!$W$43+CONFIGURACION!$W$57 -> 15.141635 | AJ7: =N7+CONFIGURACION!$X$43+CONFIGURACION!$X$57 -> 15.136576 | AK7: =N7+CONFIGURACION!$Y$43+CONFIGURACION!$Y$57 -> 15.131976 | AL7: =N7+CONFIGURACION!$Z$43+CONFIGURACION!$Z$57 -> 15.127777
B8: F-PN016 | C8: Lulo | D8: 2.5 | E8: =IFERROR(LOOKUP(9.99E+307,E$32:E$83),19.19) -> 6.5 | F8: 0.03 | G8: =E8+F8 -> 6.53 | H8: =G8/(1-CONFIGURACION!$C$6)-G8 -> 0.065959596 | I8: =G8+H8 -> 6.5959596 | J8: 0.1 | K8: =I8/(1-J8)-I8 -> 0.7328844 | L8: =I8+K8 -> 7.328844 | M8: =E4*(D8+CONFIGURACION!$D$34) -> 7.2541563 | N8: =L8+M8 -> 14.583 | O8: =N8/D8 -> 5.8332001 | P8: =N8+CONFIGURACION!$D$45+CONFIGURACION!$D$59 -> 16.708 | Q8: =N8+CONFIGURACION!$E$45+CONFIGURACION!$E$59 -> 15.6455 | R8: =N8+CONFIGURACION!$F$45-CONFIGURACION!$F$59 -> 15.041334 | S8: =N8+CONFIGURACION!$G$45-CONFIGURACION!$G$59 -> 14.92675 | T8: =N8+CONFIGURACION!$H$45-CONFIGURACION!$H$59 -> 14.858 | U8: =N8+CONFIGURACION!$I$45-CONFIGURACION!$I$59 -> 14.812167 | V8: =N8+CONFIGURACION!$J$45-CONFIGURACION!$J$59 -> 14.779429 | W8: =N8+CONFIGURACION!$K$45-CONFIGURACION!$K$59 -> 14.754875 | X8: =N8+CONFIGURACION!$L$45-CONFIGURACION!$L$59 -> 14.735778 | Y8: =N8+CONFIGURACION!$M$45-CONFIGURACION!$M$59 -> 14.7205 | Z8: =N8+CONFIGURACION!$N$45-CONFIGURACION!$N$59 -> 14.708 | AA8: =N8+CONFIGURACION!$O$45-CONFIGURACION!$O$59 -> 14.697584 | AB8: =N8+CONFIGURACION!$P$45-CONFIGURACION!$P$59 -> 14.688769 | AC8: =N8+CONFIGURACION!$Q$45-CONFIGURACION!$Q$59 -> 14.681215 | AD8: =N8+CONFIGURACION!$R$45-CONFIGURACION!$R$59 -> 14.674667 | AE8: =N8+CONFIGURACION!$S$45-CONFIGURACION!$S$59 -> 14.668938 | AF8: =N8+CONFIGURACION!$T$45-CONFIGURACION!$T$59 -> 14.663883 | AG8: =N8+CONFIGURACION!$U$45-CONFIGURACION!$U$59 -> 14.659389 | AH8: =N8+CONFIGURACION!$V$45-CONFIGURACION!$V$59 -> 14.655369 | AI8: =N8+CONFIGURACION!$W$45+CONFIGURACION!$W$59 -> 14.68925 | AJ8: =N8+CONFIGURACION!$X$45+CONFIGURACION!$X$59 -> 14.684191 | AK8: =N8+CONFIGURACION!$Y$45+CONFIGURACION!$Y$59 -> 14.679591 | AL8: =N8+CONFIGURACION!$Z$45+CONFIGURACION!$Z$59 -> 14.675392
B9: F-PPA01 | C9: Amarilla P | D9: 2.5 | E9: =IFERROR(LOOKUP(9.99E+307,F$32:F$83),19.19) -> 13.5 | F9: =CONFIGURACION!$C$5/D9 -> 0.4 | G9: =E9+F9 -> 13.9 | H9: =G9/(1-CONFIGURACION!$C$6)-G9 -> 0.14040404 | I9: =G9+H9 -> 14.040404 | J9: 0.08 | K9: =I9/(1-J9)-I9 -> 1.2209047 | L9: =I9+K9 -> 15.261309 | M9: =E4*(D9+CONFIGURACION!$D$33) -> 7.2053611 | N9: =L9+M9 -> 22.46667 | O9: =N9/D9 -> 8.9866679 | P9: =N9+CONFIGURACION!$D$44+CONFIGURACION!$D$58 -> 24.355559 | Q9: =N9+CONFIGURACION!$E$44+CONFIGURACION!$E$58 -> 23.411114 | R9: =N9+CONFIGURACION!$F$44-CONFIGURACION!$F$58 -> 22.874077 | S9: =N9+CONFIGURACION!$G$44-CONFIGURACION!$G$58 -> 22.772225 | T9: =N9+CONFIGURACION!$H$44-CONFIGURACION!$H$58 -> 22.711114 | U9: =N9+CONFIGURACION!$I$44-CONFIGURACION!$I$58 -> 22.670374 | V9: =N9+CONFIGURACION!$J$44-CONFIGURACION!$J$58 -> 22.641273 | W9: =N9+CONFIGURACION!$K$44-CONFIGURACION!$K$58 -> 22.619448 | X9: =N9+CONFIGURACION!$L$44-CONFIGURACION!$L$58 -> 22.602472 | Y9: =N9+CONFIGURACION!$M$44-CONFIGURACION!$M$58 -> 22.588892 | Z9: =N9+CONFIGURACION!$N$44-CONFIGURACION!$N$58 -> 22.577781 | AA9: =N9+CONFIGURACION!$O$44-CONFIGURACION!$O$58 -> 22.568522 | AB9: =N9+CONFIGURACION!$P$44-CONFIGURACION!$P$58 -> 22.560687 | AC9: =N9+CONFIGURACION!$Q$44-CONFIGURACION!$Q$58 -> 22.553971 | AD9: =N9+CONFIGURACION!$R$44-CONFIGURACION!$R$58 -> 22.548151 | AE9: =N9+CONFIGURACION!$S$44-CONFIGURACION!$S$58 -> 22.543059 | AF9: =N9+CONFIGURACION!$T$44-CONFIGURACION!$T$58 -> 22.538565 | AG9: =N9+CONFIGURACION!$U$44-CONFIGURACION!$U$58 -> 22.534571 | AH9: =N9+CONFIGURACION!$V$44-CONFIGURACION!$V$58 -> 22.530997 | AI9: =N9+CONFIGURACION!$W$44+CONFIGURACION!$W$58 -> 22.561114 | AJ9: =N9+CONFIGURACION!$X$44+CONFIGURACION!$X$58 -> 22.556617 | AK9: =N9+CONFIGURACION!$Y$44+CONFIGURACION!$Y$58 -> 22.552528 | AL9: =N9+CONFIGURACION!$Z$44+CONFIGURACION!$Z$58 -> 22.548795
B10: F-PSR02 | C10: Roja P | D10: 4.5 | E10: =IFERROR(LOOKUP(9.99E+307,G$32:G$83),19.19) -> 19.19 | F10: =CONFIGURACION!$C$5/D10 -> 0.22222222 | G10: =E10+F10 -> 19.412222 | H10: =G10/(1-CONFIGURACION!$C$6)-G10 -> 0.19608305 | I10: =G10+H10 -> 19.608305 | J10: 0.055 | K10: =I10/(1-J10)-I10 -> 1.1412241 | L10: =I10+K10 -> 20.749529 | M10: =E4*(D10+CONFIGURACION!$D$37) -> 12.100542 | N10: =L10+M10 -> 32.850071 | O10: =N10/D10 -> 7.3000158 | P10: =N10+CONFIGURACION!$D$48+CONFIGURACION!$D$62 -> 35.683404 | Q10: =N10+CONFIGURACION!$E$48+CONFIGURACION!$E$62 -> 34.266738 | R10: =N10+CONFIGURACION!$F$48-CONFIGURACION!$F$62 -> 33.461182 | S10: =N10+CONFIGURACION!$G$48-CONFIGURACION!$G$62 -> 33.308404 | T10: =N10+CONFIGURACION!$H$48-CONFIGURACION!$H$62 -> 33.216738 | U10: =N10+CONFIGURACION!$I$48-CONFIGURACION!$I$62 -> 33.155627 | V10: =N10+CONFIGURACION!$J$48-CONFIGURACION!$J$62 -> 33.111976 | W10: =N10+CONFIGURACION!$K$48-CONFIGURACION!$K$62 -> 33.079238 | X10: =N10+CONFIGURACION!$L$48-CONFIGURACION!$L$62 -> 33.053775 | Y10: =N10+CONFIGURACION!$M$48-CONFIGURACION!$M$62 -> 33.033404 | Z10: =N10+CONFIGURACION!$N$48-CONFIGURACION!$N$62 -> 33.016738 | AA10: =N10+CONFIGURACION!$O$48-CONFIGURACION!$O$62 -> 33.002849 | AB10: =N10+CONFIGURACION!$P$48-CONFIGURACION!$P$62 -> 32.991097 | AC10: =N10+CONFIGURACION!$Q$48-CONFIGURACION!$Q$62 -> 32.981023 | AD10: =N10+CONFIGURACION!$R$48-CONFIGURACION!$R$62 -> 32.972293 | AE10: =N10+CONFIGURACION!$S$48-CONFIGURACION!$S$62 -> 32.964654 | AF10: =N10+CONFIGURACION!$T$48-CONFIGURACION!$T$62 -> 32.957914 | AG10: =N10+CONFIGURACION!$U$48-CONFIGURACION!$U$62 -> 32.951923 | AH10: =N10+CONFIGURACION!$V$48-CONFIGURACION!$V$62 -> 32.946562 | AI10: =N10+CONFIGURACION!$W$48+CONFIGURACION!$W$62 -> 32.991738 | AJ10: =N10+CONFIGURACION!$X$48+CONFIGURACION!$X$62 -> 32.984992 | AK10: =N10+CONFIGURACION!$Y$48+CONFIGURACION!$Y$62 -> 32.978859 | AL10: =N10+CONFIGURACION!$Z$48+CONFIGURACION!$Z$62 -> 32.973259
B11: F-PSR05 | C11: Blanca P | D11: 4.5 | E11: =IFERROR(LOOKUP(9.99E+307,H$32:H$83),13.6) -> 13.6 | F11: =CONFIGURACION!$C$5/D11 -> 0.22222222 | G11: =E11+F11 -> 13.822222 | H11: =G11/(1-CONFIGURACION!$C$6)-G11 -> 0.13961841 | I11: =G11+H11 -> 13.961841 | J11: 0.055 | K11: =I11/(1-J11)-I11 -> 0.8125939 | L11: =I11+K11 -> 14.774435 | M11: =E4*(D11+CONFIGURACION!$D$37) -> 12.100542 | N11: =L11+M11 -> 26.874976 | O11: =N11/D11 -> 5.9722169 | P11: =N11+CONFIGURACION!$D$48+CONFIGURACION!$D$62 -> 29.70831 | Q11: =N11+CONFIGURACION!$E$48+CONFIGURACION!$E$62 -> 28.291643 | R11: =N11+CONFIGURACION!$F$48-CONFIGURACION!$F$62 -> 27.486087 | S11: =N11+CONFIGURACION!$G$48-CONFIGURACION!$G$62 -> 27.33331 | T11: =N11+CONFIGURACION!$H$48-CONFIGURACION!$H$62 -> 27.241643 | U11: =N11+CONFIGURACION!$I$48-CONFIGURACION!$I$62 -> 27.180532 | V11: =N11+CONFIGURACION!$J$48-CONFIGURACION!$J$62 -> 27.136881 | W11: =N11+CONFIGURACION!$K$48-CONFIGURACION!$K$62 -> 27.104143 | X11: =N11+CONFIGURACION!$L$48-CONFIGURACION!$L$62 -> 27.07868 | Y11: =N11+CONFIGURACION!$M$48-CONFIGURACION!$M$62 -> 27.05831 | Z11: =N11+CONFIGURACION!$N$48-CONFIGURACION!$N$62 -> 27.041643 | AA11: =N11+CONFIGURACION!$O$48-CONFIGURACION!$O$62 -> 27.027754 | AB11: =N11+CONFIGURACION!$P$48-CONFIGURACION!$P$62 -> 27.016002 | AC11: =N11+CONFIGURACION!$Q$48-CONFIGURACION!$Q$62 -> 27.005929 | AD11: =N11+CONFIGURACION!$R$48-CONFIGURACION!$R$62 -> 26.997198 | AE11: =N11+CONFIGURACION!$S$48-CONFIGURACION!$S$62 -> 26.98956 | AF11: =N11+CONFIGURACION!$T$48-CONFIGURACION!$T$62 -> 26.982819 | AG11: =N11+CONFIGURACION!$U$48-CONFIGURACION!$U$62 -> 26.976828 | AH11: =N11+CONFIGURACION!$V$48-CONFIGURACION!$V$62 -> 26.971467 | AI11: =N11+CONFIGURACION!$W$48+CONFIGURACION!$W$62 -> 27.016643 | AJ11: =N11+CONFIGURACION!$X$48+CONFIGURACION!$X$62 -> 27.009897 | AK11: =N11+CONFIGURACION!$Y$48+CONFIGURACION!$Y$62 -> 27.003764 | AL11: =N11+CONFIGURACION!$Z$48+CONFIGURACION!$Z$62 -> 26.998165
B12: F-PSM09 | C12: Maracuyá | D12: 2.5 | E12: =IFERROR(LOOKUP(9.99E+307,I$32:I$83),13.6) -> 7 | G12: =E12+F12 -> 7 | H12: =G12/(1-CONFIGURACION!$C$6)-G12 -> 0.070707071 | I12: =G12+H12 -> 7.0707071 | J12: 0.085 | K12: =I12/(1-J12)-I12 -> 0.65684164 | L12: =I12+K12 -> 7.7275487 | M12: =E4*(D12+CONFIGURACION!$D$34) -> 7.2541563 | N12: =L12+M12 -> 14.981705 | O12: =N12/D12 -> 5.992682 | P12: =N12+CONFIGURACION!$D$45+CONFIGURACION!$D$59 -> 17.106705 | Q12: =N12+CONFIGURACION!$E$45+CONFIGURACION!$E$59 -> 16.044205 | R12: =N12+CONFIGURACION!$F$45-CONFIGURACION!$F$59 -> 15.440038 | S12: =N12+CONFIGURACION!$G$45-CONFIGURACION!$G$59 -> 15.325455 | T12: =N12+CONFIGURACION!$H$45-CONFIGURACION!$H$59 -> 15.256705 | U12: =N12+CONFIGURACION!$I$45-CONFIGURACION!$I$59 -> 15.210872 | V12: =N12+CONFIGURACION!$J$45-CONFIGURACION!$J$59 -> 15.178134 | W12: =N12+CONFIGURACION!$K$45-CONFIGURACION!$K$59 -> 15.15358 | X12: =N12+CONFIGURACION!$L$45-CONFIGURACION!$L$59 -> 15.134483 | Y12: =N12+CONFIGURACION!$M$45-CONFIGURACION!$M$59 -> 15.119205 | Z12: =N12+CONFIGURACION!$N$45-CONFIGURACION!$N$59 -> 15.106705 | AA12: =N12+CONFIGURACION!$O$45-CONFIGURACION!$O$59 -> 15.096288 | AB12: =N12+CONFIGURACION!$P$45-CONFIGURACION!$P$59 -> 15.087474 | AC12: =N12+CONFIGURACION!$Q$45-CONFIGURACION!$Q$59 -> 15.079919 | AD12: =N12+CONFIGURACION!$R$45-CONFIGURACION!$R$59 -> 15.073372 | AE12: =N12+CONFIGURACION!$S$45-CONFIGURACION!$S$59 -> 15.067642 | AF12: =N12+CONFIGURACION!$T$45-CONFIGURACION!$T$59 -> 15.062587 | AG12: =N12+CONFIGURACION!$U$45-CONFIGURACION!$U$59 -> 15.058094 | AH12: =N12+CONFIGURACION!$V$45-CONFIGURACION!$V$59 -> 15.054073 | AI12: =N12+CONFIGURACION!$W$45+CONFIGURACION!$W$59 -> 15.087955 | AJ12: =N12+CONFIGURACION!$X$45+CONFIGURACION!$X$59 -> 15.082895 | AK12: =N12+CONFIGURACION!$Y$45+CONFIGURACION!$Y$59 -> 15.078296 | AL12: =N12+CONFIGURACION!$Z$45+CONFIGURACION!$Z$59 -> 15.074096
B13: F-TAS04 | C13: Tomate de árbol | D13: 2.5 | E13: =IFERROR(LOOKUP(9.99E+307,J$32:J$83),6.5) -> 6.5 | G13: =E13+F13 -> 6.5 | H13: =G13/(1-CONFIGURACION!$C$6)-G13 -> 0.065656566 | I13: =G13+H13 -> 6.5656566 | J13: 0.1 | K13: =I13/(1-J13)-I13 -> 0.7295174 | L13: =I13+K13 -> 7.295174 | M13: =E4*(D13+CONFIGURACION!$D$34) -> 7.2541563 | N13: =L13+M13 -> 14.54933 | O13: =N13/D13 -> 5.8197321 | P13: =N13+CONFIGURACION!$D$45+CONFIGURACION!$D$59 -> 16.67433 | Q13: =N13+CONFIGURACION!$E$45+CONFIGURACION!$E$59 -> 15.61183 | R13: =N13+CONFIGURACION!$F$45-CONFIGURACION!$F$59 -> 15.007664 | S13: =N13+CONFIGURACION!$G$45-CONFIGURACION!$G$59 -> 14.89308 | T13: =N13+CONFIGURACION!$H$45-CONFIGURACION!$H$59 -> 14.82433 | U13: =N13+CONFIGURACION!$I$45-CONFIGURACION!$I$59 -> 14.778497 | V13: =N13+CONFIGURACION!$J$45-CONFIGURACION!$J$59 -> 14.745759 | W13: =N13+CONFIGURACION!$K$45-CONFIGURACION!$K$59 -> 14.721205 | X13: =N13+CONFIGURACION!$L$45-CONFIGURACION!$L$59 -> 14.702108 | Y13: =N13+CONFIGURACION!$M$45-CONFIGURACION!$M$59 -> 14.68683 | Z13: =N13+CONFIGURACION!$N$45-CONFIGURACION!$N$59 -> 14.67433 | AA13: =N13+CONFIGURACION!$O$45-CONFIGURACION!$O$59 -> 14.663914 | AB13: =N13+CONFIGURACION!$P$45-CONFIGURACION!$P$59 -> 14.655099 | AC13: =N13+CONFIGURACION!$Q$45-CONFIGURACION!$Q$59 -> 14.647544 | AD13: =N13+CONFIGURACION!$R$45-CONFIGURACION!$R$59 -> 14.640997 | AE13: =N13+CONFIGURACION!$S$45-CONFIGURACION!$S$59 -> 14.635268 | AF13: =N13+CONFIGURACION!$T$45-CONFIGURACION!$T$59 -> 14.630213 | AG13: =N13+CONFIGURACION!$U$45-CONFIGURACION!$U$59 -> 14.625719 | AH13: =N13+CONFIGURACION!$V$45-CONFIGURACION!$V$59 -> 14.621699 | AI13: =N13+CONFIGURACION!$W$45+CONFIGURACION!$W$59 -> 14.65558 | AJ13: =N13+CONFIGURACION!$X$45+CONFIGURACION!$X$59 -> 14.650521 | AK13: =N13+CONFIGURACION!$Y$45+CONFIGURACION!$Y$59 -> 14.645921 | AL13: =N13+CONFIGURACION!$Z$45+CONFIGURACION!$Z$59 -> 14.641722
B14: F-GNB010 | C14: Guanabana | D14: 4 | E14: =IFERROR(LOOKUP(9.99E+307,K$32:K$83),13.14) -> 13.14 | F14: =CONFIGURACION!$C$5/D14 -> 0.25 | G14: =E14+F14 -> 13.39 | H14: =G14/(1-CONFIGURACION!$C$6)-G14 -> 0.13525253 | I14: =G14+H14 -> 13.525253 | J14: 0.12 | K14: =I14/(1-J14)-I14 -> 1.8443526 | L14: =I14+K14 -> 15.369605 | M14: =E4*(D14+CONFIGURACION!$D$36) -> 10.779156 | N14: =L14+M14 -> 26.148761 | O14: =N14/D14 -> 6.5371903 | P14: =N14+CONFIGURACION!$D$47+CONFIGURACION!$D$61 -> 28.273761 | Q14: =N14+CONFIGURACION!$E$47+CONFIGURACION!$E$61 -> 27.211261 | R14: =N14+CONFIGURACION!$F$47-CONFIGURACION!$F$61 -> 26.607095 | S14: =N14+CONFIGURACION!$G$47-CONFIGURACION!$G$61 -> 26.492511 | T14: =N14+CONFIGURACION!$H$47-CONFIGURACION!$H$61 -> 26.423761 | U14: =N14+CONFIGURACION!$I$47-CONFIGURACION!$I$61 -> 26.377928 | V14: =N14+CONFIGURACION!$J$47-CONFIGURACION!$J$61 -> 26.34519 | W14: =N14+CONFIGURACION!$K$47-CONFIGURACION!$K$61 -> 26.320636 | X14: =N14+CONFIGURACION!$L$47-CONFIGURACION!$L$61 -> 26.301539 | Y14: =N14+CONFIGURACION!$M$47-CONFIGURACION!$M$61 -> 26.286261 | Z14: =N14+CONFIGURACION!$N$47-CONFIGURACION!$N$61 -> 26.273761 | AA14: =N14+CONFIGURACION!$O$47-CONFIGURACION!$O$61 -> 26.263345 | AB14: =N14+CONFIGURACION!$P$47-CONFIGURACION!$P$61 -> 26.254531 | AC14: =N14+CONFIGURACION!$Q$47-CONFIGURACION!$Q$61 -> 26.246976 | AD14: =N14+CONFIGURACION!$R$47-CONFIGURACION!$R$61 -> 26.240428 | AE14: =N14+CONFIGURACION!$S$47-CONFIGURACION!$S$61 -> 26.234699 | AF14: =N14+CONFIGURACION!$T$47-CONFIGURACION!$T$61 -> 26.229644 | AG14: =N14+CONFIGURACION!$U$47-CONFIGURACION!$U$61 -> 26.22515 | AH14: =N14+CONFIGURACION!$V$47-CONFIGURACION!$V$61 -> 26.22113 | AI14: =N14+CONFIGURACION!$W$47+CONFIGURACION!$W$61 -> 26.255011 | AJ14: =N14+CONFIGURACION!$X$47+CONFIGURACION!$X$61 -> 26.249952 | AK14: =N14+CONFIGURACION!$Y$47+CONFIGURACION!$Y$61 -> 26.245352 | AL14: =N14+CONFIGURACION!$Z$47+CONFIGURACION!$Z$61 -> 26.241153
B15: F-MPS03 | C15: Melon dulce | D15: 3 | E15: =IFERROR(LOOKUP(9.99E+307,L$32:L$83),4.9) -> 5.25 | G15: =E15+F15 -> 5.25 | H15: =G15/(1-CONFIGURACION!$C$6)-G15 -> 0.053030303 | I15: =G15+H15 -> 5.3030303 | J15: 0.11 | K15: =I15/(1-J15)-I15 -> 0.65543071 | L15: =I15+K15 -> 5.958461 | M15: =E4*(D15+CONFIGURACION!$D$34) -> 8.4291563 | N15: =L15+M15 -> 14.387617 | O15: =N15/D15 -> 4.7958724 | P15: =N15+CONFIGURACION!$D$45+CONFIGURACION!$D$59 -> 16.512617 | Q15: =N15+CONFIGURACION!$E$45+CONFIGURACION!$E$59 -> 15.450117 | R15: =N15+CONFIGURACION!$F$45-CONFIGURACION!$F$59 -> 14.845951 | S15: =N15+CONFIGURACION!$G$45-CONFIGURACION!$G$59 -> 14.731367 | T15: =N15+CONFIGURACION!$H$45-CONFIGURACION!$H$59 -> 14.662617 | U15: =N15+CONFIGURACION!$I$45-CONFIGURACION!$I$59 -> 14.616784 | V15: =N15+CONFIGURACION!$J$45-CONFIGURACION!$J$59 -> 14.584046 | W15: =N15+CONFIGURACION!$K$45-CONFIGURACION!$K$59 -> 14.559492 | X15: =N15+CONFIGURACION!$L$45-CONFIGURACION!$L$59 -> 14.540395 | Y15: =N15+CONFIGURACION!$M$45-CONFIGURACION!$M$59 -> 14.525117 | Z15: =N15+CONFIGURACION!$N$45-CONFIGURACION!$N$59 -> 14.512617 | AA15: =N15+CONFIGURACION!$O$45-CONFIGURACION!$O$59 -> 14.502201 | AB15: =N15+CONFIGURACION!$P$45-CONFIGURACION!$P$59 -> 14.493386 | AC15: =N15+CONFIGURACION!$Q$45-CONFIGURACION!$Q$59 -> 14.485832 | AD15: =N15+CONFIGURACION!$R$45-CONFIGURACION!$R$59 -> 14.479284 | AE15: =N15+CONFIGURACION!$S$45-CONFIGURACION!$S$59 -> 14.473555 | AF15: =N15+CONFIGURACION!$T$45-CONFIGURACION!$T$59 -> 14.4685 | AG15: =N15+CONFIGURACION!$U$45-CONFIGURACION!$U$59 -> 14.464006 | AH15: =N15+CONFIGURACION!$V$45-CONFIGURACION!$V$59 -> 14.459986 | AI15: =N15+CONFIGURACION!$W$45+CONFIGURACION!$W$59 -> 14.493867 | AJ15: =N15+CONFIGURACION!$X$45+CONFIGURACION!$X$59 -> 14.488808 | AK15: =N15+CONFIGURACION!$Y$45+CONFIGURACION!$Y$59 -> 14.484208 | AL15: =N15+CONFIGURACION!$Z$45+CONFIGURACION!$Z$59 -> 14.480009
B16: F-CCN017 | C16: Cacao | D16: 3 | E16: 7 | F16: =CONFIGURACION!$C$5/D16 -> 0.33333333 | G16: =E16+F16 -> 7.3333333 | H16: =G16/(1-CONFIGURACION!$C$6)-G16 -> 0.074074074 | I16: =G16+H16 -> 7.4074074 | J16: 0.1 | K16: =I16/(1-J16)-I16 -> 0.82304527 | L16: =I16+K16 -> 8.2304527 | M16: =E4*(D16+CONFIGURACION!$D$35) -> 8.5755417 | N16: =L16+M16 -> 16.805994 | O16: =N16/D16 -> 5.6019981 | P16: =N16+CONFIGURACION!$D$46+CONFIGURACION!$D$60 -> 19.639328 | Q16: =N16+CONFIGURACION!$E$46+CONFIGURACION!$E$60 -> 18.222661 | R16: =N16+CONFIGURACION!$F$46-CONFIGURACION!$F$60 -> 17.417105 | S16: =N16+CONFIGURACION!$G$46-CONFIGURACION!$G$60 -> 17.264328 | T16: =N16+CONFIGURACION!$H$46-CONFIGURACION!$H$60 -> 17.172661 | U16: =N16+CONFIGURACION!$I$46-CONFIGURACION!$I$60 -> 17.11155 | V16: =N16+CONFIGURACION!$J$46-CONFIGURACION!$J$60 -> 17.067899 | W16: =N16+CONFIGURACION!$K$46-CONFIGURACION!$K$60 -> 17.035161 | X16: =N16+CONFIGURACION!$L$46-CONFIGURACION!$L$60 -> 17.009698 | Y16: =N16+CONFIGURACION!$M$46-CONFIGURACION!$M$60 -> 16.989328 | Z16: =N16+CONFIGURACION!$N$46-CONFIGURACION!$N$60 -> 16.972661 | AA16: =N16+CONFIGURACION!$O$46-CONFIGURACION!$O$60 -> 16.958772 | AB16: =N16+CONFIGURACION!$P$46-CONFIGURACION!$P$60 -> 16.94702 | AC16: =N16+CONFIGURACION!$Q$46-CONFIGURACION!$Q$60 -> 16.936947 | AD16: =N16+CONFIGURACION!$R$46-CONFIGURACION!$R$60 -> 16.928217 | AE16: =N16+CONFIGURACION!$S$46-CONFIGURACION!$S$60 -> 16.920578 | AF16: =N16+CONFIGURACION!$T$46-CONFIGURACION!$T$60 -> 16.913837 | AG16: =N16+CONFIGURACION!$U$46-CONFIGURACION!$U$60 -> 16.907846 | AH16: =N16+CONFIGURACION!$V$46-CONFIGURACION!$V$60 -> 16.902486 | AI16: =N16+CONFIGURACION!$W$46+CONFIGURACION!$W$60 -> 16.947661 | AJ16: =N16+CONFIGURACION!$X$46+CONFIGURACION!$X$60 -> 16.940915 | AK16: =N16+CONFIGURACION!$Y$46+CONFIGURACION!$Y$60 -> 16.934782 | AL16: =N16+CONFIGURACION!$Z$46+CONFIGURACION!$Z$60 -> 16.929183
B17: F-BCC013 | C17: Babaco | D17: 3 | E17: =IFERROR(LOOKUP(9.99E+307,N$32:N$83),8.6) -> 8.6 | F17: =CONFIGURACION!$C$5/D17 -> 0.33333333 | G17: 9.93 | H17: =G17/(1-CONFIGURACION!$C$6)-G17 -> 0.10030303 | I17: =G17+H17 -> 10.030303 | J17: 0.1 | K17: =I17/(1-J17)-I17 -> 1.1144781 | L17: =I17+K17 -> 11.144781 | M17: =E4*(D17+CONFIGURACION!$D$35) -> 8.5755417 | N17: =L17+M17 -> 19.720323 | O17: =N17/D17 -> 6.5734409 | P17: =N17+CONFIGURACION!$D$46+CONFIGURACION!$D$60 -> 22.553656 | Q17: =N17+CONFIGURACION!$E$46+CONFIGURACION!$E$60 -> 21.136989 | R17: =N17+CONFIGURACION!$F$46-CONFIGURACION!$F$60 -> 20.331434 | S17: =N17+CONFIGURACION!$G$46-CONFIGURACION!$G$60 -> 20.178656 | T17: =N17+CONFIGURACION!$H$46-CONFIGURACION!$H$60 -> 20.086989 | U17: =N17+CONFIGURACION!$I$46-CONFIGURACION!$I$60 -> 20.025878 | V17: =N17+CONFIGURACION!$J$46-CONFIGURACION!$J$60 -> 19.982228 | W17: =N17+CONFIGURACION!$K$46-CONFIGURACION!$K$60 -> 19.949489 | X17: =N17+CONFIGURACION!$L$46-CONFIGURACION!$L$60 -> 19.924027 | Y17: =N17+CONFIGURACION!$M$46-CONFIGURACION!$M$60 -> 19.903656 | Z17: =N17+CONFIGURACION!$N$46-CONFIGURACION!$N$60 -> 19.886989 | AA17: =N17+CONFIGURACION!$O$46-CONFIGURACION!$O$60 -> 19.873101 | AB17: =N17+CONFIGURACION!$P$46-CONFIGURACION!$P$60 -> 19.861348 | AC17: =N17+CONFIGURACION!$Q$46-CONFIGURACION!$Q$60 -> 19.851275 | AD17: =N17+CONFIGURACION!$R$46-CONFIGURACION!$R$60 -> 19.842545 | AE17: =N17+CONFIGURACION!$S$46-CONFIGURACION!$S$60 -> 19.834906 | AF17: =N17+CONFIGURACION!$T$46-CONFIGURACION!$T$60 -> 19.828166 | AG17: =N17+CONFIGURACION!$U$46-CONFIGURACION!$U$60 -> 19.822175 | AH17: =N17+CONFIGURACION!$V$46-CONFIGURACION!$V$60 -> 19.816814 | AI17: =N17+CONFIGURACION!$W$46+CONFIGURACION!$W$60 -> 19.861989 | AJ17: =N17+CONFIGURACION!$X$46+CONFIGURACION!$X$60 -> 19.855243 | AK17: =N17+CONFIGURACION!$Y$46+CONFIGURACION!$Y$60 -> 19.849111 | AL17: =N17+CONFIGURACION!$Z$46+CONFIGURACION!$Z$60 -> 19.843511
B18: F-AHSS012 | C18: Aguacate | D18: 4 | E18: =IFERROR(LOOKUP(9.99E+307,O$32:O$83),8.55) -> 8.55 | F18: =CONFIGURACION!$C$5/D18 -> 0.25 | G18: =E18+F18 -> 8.8 | H18: =G18/(1-CONFIGURACION!$C$6)-G18 -> 0.088888889 | I18: =G18+H18 -> 8.8888889 | J18: 0.06 | K18: =I18/(1-J18)-I18 -> 0.56737589 | L18: =I18+K18 -> 9.4562648 | M18: =E4*(D18+CONFIGURACION!$D$36) -> 10.779156 | N18: =L18+M18 -> 20.235421 | O18: =N18/D18 -> 5.0588553 | P18: =N18+CONFIGURACION!$D$47+CONFIGURACION!$D$61 -> 22.360421 | Q18: =N18+CONFIGURACION!$E$47+CONFIGURACION!$E$61 -> 21.297921 | R18: =N18+CONFIGURACION!$F$47-CONFIGURACION!$F$61 -> 20.693754 | S18: =N18+CONFIGURACION!$G$47-CONFIGURACION!$G$61 -> 20.579171 | T18: =N18+CONFIGURACION!$H$47-CONFIGURACION!$H$61 -> 20.510421 | U18: =N18+CONFIGURACION!$I$47-CONFIGURACION!$I$61 -> 20.464588 | V18: =N18+CONFIGURACION!$J$47-CONFIGURACION!$J$61 -> 20.43185 | W18: =N18+CONFIGURACION!$K$47-CONFIGURACION!$K$61 -> 20.407296 | X18: =N18+CONFIGURACION!$L$47-CONFIGURACION!$L$61 -> 20.388199 | Y18: =N18+CONFIGURACION!$M$47-CONFIGURACION!$M$61 -> 20.372921 | Z18: =N18+CONFIGURACION!$N$47-CONFIGURACION!$N$61 -> 20.360421 | AA18: =N18+CONFIGURACION!$O$47-CONFIGURACION!$O$61 -> 20.350004 | AB18: =N18+CONFIGURACION!$P$47-CONFIGURACION!$P$61 -> 20.34119 | AC18: =N18+CONFIGURACION!$Q$47-CONFIGURACION!$Q$61 -> 20.333635 | AD18: =N18+CONFIGURACION!$R$47-CONFIGURACION!$R$61 -> 20.327088 | AE18: =N18+CONFIGURACION!$S$47-CONFIGURACION!$S$61 -> 20.321359 | AF18: =N18+CONFIGURACION!$T$47-CONFIGURACION!$T$61 -> 20.316303 | AG18: =N18+CONFIGURACION!$U$47-CONFIGURACION!$U$61 -> 20.31181 | AH18: =N18+CONFIGURACION!$V$47-CONFIGURACION!$V$61 -> 20.307789 | AI18: =N18+CONFIGURACION!$W$47+CONFIGURACION!$W$61 -> 20.341671 | AJ18: =N18+CONFIGURACION!$X$47+CONFIGURACION!$X$61 -> 20.336612 | AK18: =N18+CONFIGURACION!$Y$47+CONFIGURACION!$Y$61 -> 20.332012 | AL18: =N18+CONFIGURACION!$Z$47+CONFIGURACION!$Z$61 -> 20.327812
B19: F-BBB06 | C19: Baby banano | D19: 3.5 | E19: =IFERROR(LOOKUP(9.99E+307,P$32:P$83),13.2) -> 11.5 | F19: =CONFIGURACION!$C$5/D19 -> 0.28571429 | G19: =E19+F19 -> 11.785714 | H19: =G19/(1-CONFIGURACION!$C$6)-G19 -> 0.11904762 | I19: =G19+H19 -> 11.904762 | J19: 0.06 | K19: =I19/(1-J19)-I19 -> 0.75987842 | L19: =I19+K19 -> 12.66464 | M19: =E4*(D19+CONFIGURACION!$D$36) -> 9.6041563 | N19: =L19+M19 -> 22.268797 | O19: =N19/D19 -> 6.3625133 | P19: =N19+CONFIGURACION!$D$47+CONFIGURACION!$D$61 -> 24.393797 | Q19: =N19+CONFIGURACION!$E$47+CONFIGURACION!$E$61 -> 23.331297 | R19: =N19+CONFIGURACION!$F$47-CONFIGURACION!$F$61 -> 22.72713 | S19: =N19+CONFIGURACION!$G$47-CONFIGURACION!$G$61 -> 22.612547 | T19: =N19+CONFIGURACION!$H$47-CONFIGURACION!$H$61 -> 22.543797 | U19: =N19+CONFIGURACION!$I$47-CONFIGURACION!$I$61 -> 22.497963 | V19: =N19+CONFIGURACION!$J$47-CONFIGURACION!$J$61 -> 22.465225 | W19: =N19+CONFIGURACION!$K$47-CONFIGURACION!$K$61 -> 22.440672 | X19: =N19+CONFIGURACION!$L$47-CONFIGURACION!$L$61 -> 22.421574 | Y19: =N19+CONFIGURACION!$M$47-CONFIGURACION!$M$61 -> 22.406297 | Z19: =N19+CONFIGURACION!$N$47-CONFIGURACION!$N$61 -> 22.393797 | AA19: =N19+CONFIGURACION!$O$47-CONFIGURACION!$O$61 -> 22.38338 | AB19: =N19+CONFIGURACION!$P$47-CONFIGURACION!$P$61 -> 22.374566 | AC19: =N19+CONFIGURACION!$Q$47-CONFIGURACION!$Q$61 -> 22.367011 | AD19: =N19+CONFIGURACION!$R$47-CONFIGURACION!$R$61 -> 22.360463 | AE19: =N19+CONFIGURACION!$S$47-CONFIGURACION!$S$61 -> 22.354734 | AF19: =N19+CONFIGURACION!$T$47-CONFIGURACION!$T$61 -> 22.349679 | AG19: =N19+CONFIGURACION!$U$47-CONFIGURACION!$U$61 -> 22.345185 | AH19: =N19+CONFIGURACION!$V$47-CONFIGURACION!$V$61 -> 22.341165 | AI19: =N19+CONFIGURACION!$W$47+CONFIGURACION!$W$61 -> 22.375047 | AJ19: =N19+CONFIGURACION!$X$47+CONFIGURACION!$X$61 -> 22.369987 | AK19: =N19+CONFIGURACION!$Y$47+CONFIGURACION!$Y$61 -> 22.365387 | AL19: =N19+CONFIGURACION!$Z$47+CONFIGURACION!$Z$61 -> 22.361188
B20: F-ZPT020 | C20: Zapote Mamey | D20: 4 | E20: =IFERROR(LOOKUP(9.99E+307,Q$32:Q$83),13.2) -> 12 | F20: =CONFIGURACION!$C$5/D20 -> 0.25 | G20: =E20+F20 -> 12.25 | H20: =G20/(1-CONFIGURACION!$C$6)-G20 -> 0.12373737 | I20: =G20+H20 -> 12.373737 | J20: 0.18 | K20: =I20/(1-J20)-I20 -> 2.7161863 | L20: =I20+K20 -> 15.089924 | M20: =E4*(D20+CONFIGURACION!$D$36) -> 10.779156 | N20: =L20+M20 -> 25.86908 | O20: =N20/D20 -> 6.46727 | P20: =N20+CONFIGURACION!$D$47+CONFIGURACION!$D$61 -> 27.99408 | Q20: =N20+CONFIGURACION!$E$47+CONFIGURACION!$E$61 -> 26.93158 | R20: =N20+CONFIGURACION!$F$47-CONFIGURACION!$F$61 -> 26.327413 | S20: =N20+CONFIGURACION!$G$47-CONFIGURACION!$G$61 -> 26.21283 | T20: =N20+CONFIGURACION!$H$47-CONFIGURACION!$H$61 -> 26.14408 | U20: =N20+CONFIGURACION!$I$47-CONFIGURACION!$I$61 -> 26.098247 | V20: =N20+CONFIGURACION!$J$47-CONFIGURACION!$J$61 -> 26.065508 | W20: =N20+CONFIGURACION!$K$47-CONFIGURACION!$K$61 -> 26.040955 | X20: =N20+CONFIGURACION!$L$47-CONFIGURACION!$L$61 -> 26.021858 | Y20: =N20+CONFIGURACION!$M$47-CONFIGURACION!$M$61 -> 26.00658 | Z20: =N20+CONFIGURACION!$N$47-CONFIGURACION!$N$61 -> 25.99408 | AA20: =N20+CONFIGURACION!$O$47-CONFIGURACION!$O$61 -> 25.983663 | AB20: =N20+CONFIGURACION!$P$47-CONFIGURACION!$P$61 -> 25.974849 | AC20: =N20+CONFIGURACION!$Q$47-CONFIGURACION!$Q$61 -> 25.967294 | AD20: =N20+CONFIGURACION!$R$47-CONFIGURACION!$R$61 -> 25.960747 | AE20: =N20+CONFIGURACION!$S$47-CONFIGURACION!$S$61 -> 25.955017 | AF20: =N20+CONFIGURACION!$T$47-CONFIGURACION!$T$61 -> 25.949962 | AG20: =N20+CONFIGURACION!$U$47-CONFIGURACION!$U$61 -> 25.945469 | AH20: =N20+CONFIGURACION!$V$47-CONFIGURACION!$V$61 -> 25.941448 | AI20: =N20+CONFIGURACION!$W$47+CONFIGURACION!$W$61 -> 25.97533 | AJ20: =N20+CONFIGURACION!$X$47+CONFIGURACION!$X$61 -> 25.97027 | AK20: =N20+CONFIGURACION!$Y$47+CONFIGURACION!$Y$61 -> 25.965671 | AL20: =N20+CONFIGURACION!$Z$47+CONFIGURACION!$Z$61 -> 25.961471
B21: F-TX020 | C21: Taxo | D21: 2.5 | E21: 6.75 | G21: =E21+F21 -> 6.75 | H21: =G21/(1-CONFIGURACION!$C$6)-G21 -> 0.068181818 | I21: =G21+H21 -> 6.8181818 | J21: 0.11 | K21: =I21/(1-J21)-I21 -> 0.84269663 | L21: =I21+K21 -> 7.6608784 | M21: =E4*(D21+CONFIGURACION!$D$34) -> 7.2541563 | N21: =L21+M21 -> 14.915035 | O21: =N21/D21 -> 5.9660139 | P21: =N21+CONFIGURACION!$D$45+CONFIGURACION!$D$59 -> 17.040035 | Q21: =N21+CONFIGURACION!$E$45+CONFIGURACION!$E$59 -> 15.977535 | R21: =N21+CONFIGURACION!$F$45-CONFIGURACION!$F$59 -> 15.373368 | S21: =N21+CONFIGURACION!$G$45-CONFIGURACION!$G$59 -> 15.258785 | T21: =N21+CONFIGURACION!$H$45-CONFIGURACION!$H$59 -> 15.190035 | U21: =N21+CONFIGURACION!$I$45-CONFIGURACION!$I$59 -> 15.144201 | V21: =N21+CONFIGURACION!$J$45-CONFIGURACION!$J$59 -> 15.111463 | W21: =N21+CONFIGURACION!$K$45-CONFIGURACION!$K$59 -> 15.08691 | X21: =N21+CONFIGURACION!$L$45-CONFIGURACION!$L$59 -> 15.067812 | Y21: =N21+CONFIGURACION!$M$45-CONFIGURACION!$M$59 -> 15.052535 | Z21: =N21+CONFIGURACION!$N$45-CONFIGURACION!$N$59 -> 15.040035 | AA21: =N21+CONFIGURACION!$O$45-CONFIGURACION!$O$59 -> 15.029618 | AB21: =N21+CONFIGURACION!$P$45-CONFIGURACION!$P$59 -> 15.020804 | AC21: =N21+CONFIGURACION!$Q$45-CONFIGURACION!$Q$59 -> 15.013249 | AD21: =N21+CONFIGURACION!$R$45-CONFIGURACION!$R$59 -> 15.006701 | AE21: =N21+CONFIGURACION!$S$45-CONFIGURACION!$S$59 -> 15.000972 | AF21: =N21+CONFIGURACION!$T$45-CONFIGURACION!$T$59 -> 14.995917 | AG21: =N21+CONFIGURACION!$U$45-CONFIGURACION!$U$59 -> 14.991424 | AH21: =N21+CONFIGURACION!$V$45-CONFIGURACION!$V$59 -> 14.987403 | AI21: =N21+CONFIGURACION!$W$45+CONFIGURACION!$W$59 -> 15.021285 | AJ21: =N21+CONFIGURACION!$X$45+CONFIGURACION!$X$59 -> 15.016225 | AK21: =N21+CONFIGURACION!$Y$45+CONFIGURACION!$Y$59 -> 15.011626 | AL21: =N21+CONFIGURACION!$Z$45+CONFIGURACION!$Z$59 -> 15.007426
B22: F-UVP08 | C22: Physalis | D22: 1.25 | E22: =IFERROR(LOOKUP(9.99E+307,S$32:S$83),8.5) -> 8.5 | G22: =E22+F22 -> 8.5 | H22: =G22/(1-CONFIGURACION!$C$6)-G22 -> 0.085858586 | I22: =G22+H22 -> 8.5858586 | J22: 0.11 | K22: =I22/(1-J22)-I22 -> 1.0611735 | L22: =I22+K22 -> 9.6470321 | M22: =E4*(D22+CONFIGURACION!$D$38) -> 4.3166563 | N22: =L22+M22 -> 13.963688 | O22: =N22/D22 -> 11.170951 | P22: =N22+CONFIGURACION!$D$49+CONFIGURACION!$D$63 -> 16.088688 | Q22: =N22+CONFIGURACION!$E$49+CONFIGURACION!$E$63 -> 15.026188 | R22: =N22+CONFIGURACION!$F$49-CONFIGURACION!$F$63 -> 14.422022 | S22: =N22+CONFIGURACION!$G$49-CONFIGURACION!$G$63 -> 14.307438 | T22: =N22+CONFIGURACION!$H$49-CONFIGURACION!$H$63 -> 14.238688 | U22: =N22+CONFIGURACION!$I$49-CONFIGURACION!$I$63 -> 14.192855 | V22: =N22+CONFIGURACION!$J$49-CONFIGURACION!$J$63 -> 14.160117 | W22: =N22+CONFIGURACION!$K$49-CONFIGURACION!$K$63 -> 14.135563 | X22: =N22+CONFIGURACION!$L$49-CONFIGURACION!$L$63 -> 14.116466 | Y22: =N22+CONFIGURACION!$M$49-CONFIGURACION!$M$63 -> 14.101188 | Z22: =N22+CONFIGURACION!$N$49-CONFIGURACION!$N$63 -> 14.088688 | AA22: =N22+CONFIGURACION!$O$49-CONFIGURACION!$O$63 -> 14.078272 | AB22: =N22+CONFIGURACION!$P$49-CONFIGURACION!$P$63 -> 14.069458 | AC22: =N22+CONFIGURACION!$Q$49-CONFIGURACION!$Q$63 -> 14.061903 | AD22: =N22+CONFIGURACION!$R$49-CONFIGURACION!$R$63 -> 14.055355 | AE22: =N22+CONFIGURACION!$S$49-CONFIGURACION!$S$63 -> 14.049626 | AF22: =N22+CONFIGURACION!$T$49-CONFIGURACION!$T$63 -> 14.044571 | AG22: =N22+CONFIGURACION!$U$49-CONFIGURACION!$U$63 -> 14.040077 | AH22: =N22+CONFIGURACION!$V$49-CONFIGURACION!$V$63 -> 14.036057 | AI22: =N22+CONFIGURACION!$W$49+CONFIGURACION!$W$63 -> 14.069938 | AJ22: =N22+CONFIGURACION!$X$49+CONFIGURACION!$X$63 -> 14.064879 | AK22: =N22+CONFIGURACION!$Y$49+CONFIGURACION!$Y$63 -> 14.060279 | AL22: =N22+CONFIGURACION!$Z$49+CONFIGURACION!$Z$63 -> 14.05608
B23: F-UVP07 | C23: Physalis - husk | D23: 1.5 | E23: =IFERROR(LOOKUP(9.99E+307,T$32:T$83),7) -> 7.25 | G23: =E23+F23 -> 7.25 | H23: =G23/(1-CONFIGURACION!$C$6)-G23 -> 0.073232323 | I23: =G23+H23 -> 7.3232323 | J23: 0.11 | K23: =I23/(1-J23)-I23 -> 0.9051186 | L23: =I23+K23 -> 8.2283509 | M23: =E4*(D23+CONFIGURACION!$D$38) -> 4.9041563 | N23: =L23+M23 -> 13.132507 | O23: =N23/D23 -> 8.7550048 | P23: =N23+CONFIGURACION!$D$50+CONFIGURACION!$D$64 -> 15.257507 | Q23: =N23+CONFIGURACION!$E$50+CONFIGURACION!$E$64 -> 14.195007 | R23: =N23+CONFIGURACION!$F$50-CONFIGURACION!$F$64 -> 13.590841 | S23: =N23+CONFIGURACION!$G$50-CONFIGURACION!$G$64 -> 13.476257 | T23: =N23+CONFIGURACION!$H$50-CONFIGURACION!$H$64 -> 13.407507 | U23: =N23+CONFIGURACION!$I$50-CONFIGURACION!$I$64 -> 13.361674 | V23: =N23+CONFIGURACION!$J$50-CONFIGURACION!$J$64 -> 13.328936 | W23: =N23+CONFIGURACION!$K$50-CONFIGURACION!$K$64 -> 13.304382 | X23: =N23+CONFIGURACION!$L$50-CONFIGURACION!$L$64 -> 13.285285 | Y23: =N23+CONFIGURACION!$M$50-CONFIGURACION!$M$64 -> 13.270007 | Z23: =N23+CONFIGURACION!$N$50-CONFIGURACION!$N$64 -> 13.257507 | AA23: =N23+CONFIGURACION!$O$50-CONFIGURACION!$O$64 -> 13.247091 | AB23: =N23+CONFIGURACION!$P$50-CONFIGURACION!$P$64 -> 13.238276 | AC23: =N23+CONFIGURACION!$Q$50-CONFIGURACION!$Q$64 -> 13.230721 | AD23: =N23+CONFIGURACION!$R$50-CONFIGURACION!$R$64 -> 13.224174 | AE23: =N23+CONFIGURACION!$S$50-CONFIGURACION!$S$64 -> 13.218445 | AF23: =N23+CONFIGURACION!$T$50-CONFIGURACION!$T$64 -> 13.21339 | AG23: =N23+CONFIGURACION!$U$50-CONFIGURACION!$U$64 -> 13.208896 | AH23: =N23+CONFIGURACION!$V$50-CONFIGURACION!$V$64 -> 13.204876 | AI23: =N23+CONFIGURACION!$W$50+CONFIGURACION!$W$64 -> 13.238757 | AJ23: =N23+CONFIGURACION!$X$50+CONFIGURACION!$X$64 -> 13.233698 | AK23: =N23+CONFIGURACION!$Y$50+CONFIGURACION!$Y$64 -> 13.229098 | AL23: =N23+CONFIGURACION!$Z$50+CONFIGURACION!$Z$64 -> 13.224898
B24: F-SLK011 | C24: Salack | D24: 2.5 | E24: 12.2 | F24: =CONFIGURACION!$C$5/D24 -> 0.4 | G24: =E24+F24 -> 12.6 | H24: =G24/(1-CONFIGURACION!$C$6)-G24 -> 0.12727273 | I24: =G24+H24 -> 12.727273 | J24: 0.1 | K24: =I24/(1-J24)-I24 -> 1.4141414 | L24: =I24+K24 -> 14.141414 | M24: =E4*(D24+CONFIGURACION!$D$38) -> 7.2541563 | N24: =L24+M24 -> 21.39557 | O24: =N24/D24 -> 8.5582282 | P24: =N24+CONFIGURACION!$D$45+CONFIGURACION!$D$59 -> 23.52057 | Q24: =N24+CONFIGURACION!$E$45+CONFIGURACION!$E$59 -> 22.45807 | R24: =N24+CONFIGURACION!$F$45-CONFIGURACION!$F$59 -> 21.853904 | S24: =N24+CONFIGURACION!$G$45-CONFIGURACION!$G$59 -> 21.73932 | T24: =N24+CONFIGURACION!$H$45-CONFIGURACION!$H$59 -> 21.67057 | U24: =N24+CONFIGURACION!$I$45-CONFIGURACION!$I$59 -> 21.624737 | V24: =N24+CONFIGURACION!$J$45-CONFIGURACION!$J$59 -> 21.591999 | W24: =N24+CONFIGURACION!$K$45-CONFIGURACION!$K$59 -> 21.567445 | X24: =N24+CONFIGURACION!$L$45-CONFIGURACION!$L$59 -> 21.548348 | Y24: =N24+CONFIGURACION!$M$45-CONFIGURACION!$M$59 -> 21.53307 | Z24: =N24+CONFIGURACION!$N$45-CONFIGURACION!$N$59 -> 21.52057 | AA24: =N24+CONFIGURACION!$O$45-CONFIGURACION!$O$59 -> 21.510154 | AB24: =N24+CONFIGURACION!$P$45-CONFIGURACION!$P$59 -> 21.50134 | AC24: =N24+CONFIGURACION!$Q$45-CONFIGURACION!$Q$59 -> 21.493785 | AD24: =N24+CONFIGURACION!$R$45-CONFIGURACION!$R$59 -> 21.487237 | AE24: =N24+CONFIGURACION!$S$45-CONFIGURACION!$S$59 -> 21.481508 | AF24: =N24+CONFIGURACION!$T$45-CONFIGURACION!$T$59 -> 21.476453 | AG24: =N24+CONFIGURACION!$U$45-CONFIGURACION!$U$59 -> 21.471959 | AH24: =N24+CONFIGURACION!$V$45-CONFIGURACION!$V$59 -> 21.467939 | AI24: =N24+CONFIGURACION!$W$45+CONFIGURACION!$W$59 -> 21.50182 | AJ24: =N24+CONFIGURACION!$X$45+CONFIGURACION!$X$59 -> 21.496761 | AK24: =N24+CONFIGURACION!$Y$45+CONFIGURACION!$Y$59 -> 21.492161 | AL24: =N24+CONFIGURACION!$Z$45+CONFIGURACION!$Z$59 -> 21.487962
B25: F-CAZ021 | C25: Caña de azúcar | D25: 4 | E25: 10.72 | F25: =CONFIGURACION!$C$5/D25 -> 0.25 | G25: =E25+F25 -> 10.97 | H25: =G25/(1-CONFIGURACION!$C$6)-G25 -> 0.11080808 | I25: =G25+H25 -> 11.080808 | J25: 0.11 | K25: =I25/(1-J25)-I25 -> 1.3695381 | L25: =I25+K25 -> 12.450346 | M25: =E4*(D25+CONFIGURACION!$D$39) -> 10.779156 | N25: =L25+M25 -> 23.229502 | O25: =N25/D25 -> 5.8073756 | P25: =N25+CONFIGURACION!$D$47 -> 24.979502 | Q25: =$N$25+CONFIGURACION!E47 -> 24.104502 | R25: =$N$25+CONFIGURACION!F47-CONFIGURACION!$F$61 -> 23.687836 | S25: =$N$25+CONFIGURACION!G47 -> 23.667002 | T25: =$N$25+CONFIGURACION!H47 -> 23.579502 | U25: =$N$25+CONFIGURACION!I47 -> 23.521169 | V25: =$N$25+CONFIGURACION!J47 -> 23.479502 | W25: =$N$25+CONFIGURACION!K47 -> 23.448252 | X25: =$N$25+CONFIGURACION!L47 -> 23.423947 | Y25: =$N$25+CONFIGURACION!M47 -> 23.404502 | Z25: =$N$25+CONFIGURACION!N47 -> 23.388593 | AA25: =$N$25+CONFIGURACION!O47 -> 23.375336
B28: ℹ Cambiar destino en C4 → flete se actualiza solo · Cambiar DUE/cajas en CONFIGURACION → pallets se actualizan solos · Tipo de cambio: actualización automática BCE al abrir (o manual en CONFIGURACION C13) · Fórmula flete: Tarifa × (kg neto + tara + peso pallet ÷ cajas/pallet)
A29: HISTORIAL SEMANAL DE PRECIOS · Añade una fila por semana con los precios nuevos · La tabla de arriba se actualiza automáticamente con el último precio ingresado
B31: Semana # | C31: Fecha | D31: Granadilla $/caja | E31: Lulo $/caja | F31: Amarilla P $/caja | G31: Roja P $/caja | H31: Blanca P $/caja | I31: Maracuyá $/caja | J31: Tomate de árbol $/caja | K31: Guanabana $/caja | L31: Melon dulce $/caja | M31: Cacao $/caja | N31: Babaco $/caja | O31: Aguacate $/caja | P31: Baby banano $/caja | Q31: Zapote $/caja | R31: Taxo $/caja | S31: Physalis $/caja | T31: Physalis - husk $/caja | U31: Notas
B32: 20 | C32: 12/05/2026 | D32: 8.35 | E32: 6.5 | F32: 15.5 | G32: 19.19 | H32: 13.6 | I32: 7 | J32: 6.5 | K32: 13.14 | L32: 4.9 | M32: 6 | N32: 8.6 | O32: 8.55 | P32: 11.5 | Q32: 12 | R32: 6.5 | S32: 8.5 | T32: 7 | U32: Precios iniciales mayo 2026
B33: 21 | C33: 46160 | D33: 7.95 | E33: 6.5 | F33: 13.5 | L33: 5.25 | R33: 6.7 | T33: 7.25
B34: =IF(C34="","",ROWS($C$33:C34))
B35: =IF(C35="","",ROWS($C$33:C35))
B36: =IF(C36="","",ROWS($C$33:C36))
B37: =IF(C37="","",ROWS($C$33:C37))
B38: =IF(C38="","",ROWS($C$33:C38))
B39: =IF(C39="","",ROWS($C$33:C39))
B40: =IF(C40="","",ROWS($C$33:C40))
B41: =IF(C41="","",ROWS($C$33:C41))
B42: =IF(C42="","",ROWS($C$33:C42))
B43: =IF(C43="","",ROWS($C$33:C43))
B44: =IF(C44="","",ROWS($C$33:C44))
B45: =IF(C45="","",ROWS($C$33:C45))
...

Sheet TODOS DESTINOS
A1: EXPORT HARET · COMPARACIÓN TODOS LOS DESTINOS
B2: Vigente 12/05/2026 | CIF sin DUE | Pal $ = precio USD | Pal € = precio EUR (BCE) | K2: PALLETS: | L2: 1 | M2: ← 1 a 12
B3: Código | C3: Producto | D3: kg | E3: Madrid/España | H3: París/Francia | K3: Londres/UK | N3: Suiza | Q3: Países Bajos | T3: Dubai/EAU | W3: Nueva York/USA | Z3: Miami/USA | AC3: Francia (otros)
B4: Código | C4: Producto | D4: kg | E4: CIF USD | F4: =TEXT($L$2,"0")&" Pal $" -> 1 Pal $ | G4: =TEXT($L$2,"0")&" Pal €" -> 1 Pal € | H4: CIF USD | I4: =TEXT($L$2,"0")&" Pal $" -> 1 Pal $ | J4: =TEXT($L$2,"0")&" Pal €" -> 1 Pal € | K4: CIF USD | L4: =TEXT($L$2,"0")&" Pal $" -> 1 Pal $ | M4: =TEXT($L$2,"0")&" Pal €" -> 1 Pal € | N4: CIF USD | O4: =TEXT($L$2,"0")&" Pal $" -> 1 Pal $ | P4: =TEXT($L$2,"0")&" Pal €" -> 1 Pal € | Q4: CIF USD | R4: =TEXT($L$2,"0")&" Pal $" -> 1 Pal $ | S4: =TEXT($L$2,"0")&" Pal €" -> 1 Pal € | T4: CIF USD | U4: =TEXT($L$2,"0")&" Pal $" -> 1 Pal $ | V4: =TEXT($L$2,"0")&" Pal €" -> 1 Pal € | W4: CIF USD | X4: =TEXT($L$2,"0")&" Pal $" -> 1 Pal $ | Y4: =TEXT($L$2,"0")&" Pal €" -> 1 Pal € | Z4: CIF USD | AA4: =TEXT($L$2,"0")&" Pal $" -> 1 Pal $ | AB4: =TEXT($L$2,"0")&" Pal €" -> 1 Pal € | AC4: CIF USD | AD4: =TEXT($L$2,"0")&" Pal $" -> 1 Pal $ | AE4: =TEXT($L$2,"0")&" Pal €" -> 1 Pal €
B5: F-PSG10 | C5: Granadilla | D5: 2 | E5: ='TABLA PRECIOS'!$L$7+CONFIGURACION!$C$19*('TABLA PRECIOS'!$D$7+CONFIGURACION!$D$32) -> 15.035385 | F5: ='TABLA PRECIOS'!$L$7+CONFIGURACION!$C$19*('TABLA PRECIOS'!$D$7+CONFIGURACION!$D$32)+IF($L$2=1,CONFIGURACION!$C$7/CONFIGURACION!$C$32,-CONFIGURACION!$C$7/($L$2*CONFIGURACION!$C$32)-CONFIGURACION!$C$55/($L$2*CONFIGURACION!$C$32)) -> 16.785385 | G5: =('TABLA PRECIOS'!$L$7+CONFIGURACION!$C$19*('TABLA PRECIOS'!$D$7+CONFIGURACION!$D$32)+IF($L$2=1,CONFIGURACION!$C$7/CONFIGURACION!$C$32,-CONFIGURACION!$C$7/($L$2*CONFIGURACION!$C$32)-CONFIGURACION!$C$55/($L$2*CONFIGURACION!$C$32)))/CONFIGURACION!$C$12+IF($L$2=1,0,-CONFIGURACION!$C$55/($L$2*CONFIGURACION!$C$32)) -> 14.420434 | H5: ='TABLA PRECIOS'!$L$7+CONFIGURACION!$C$20*('TABLA PRECIOS'!$D$7+CONFIGURACION!$D$32) -> 16.328823 | I5: ='TABLA PRECIOS'!$L$7+CONFIGURACION!$C$20*('TABLA PRECIOS'!$D$7+CONFIGURACION!$D$32)+IF($L$2=1,CONFIGURACION!$C$7/CONFIGURACION!$C$32,-CONFIGURACION!$C$7/($L$2*CONFIGURACION!$C$32)-CONFIGURACION!$C$55/($L$2*CONFIGURACION!$C$32)) -> 18.078823 | J5: =('TABLA PRECIOS'!$L$7+CONFIGURACION!$C$20*('TABLA PRECIOS'!$D$7+CONFIGURACION!$D$32)+IF($L$2=1,CONFIGURACION!$C$7/CONFIGURACION!$C$32,-CONFIGURACION!$C$7/($L$2*CONFIGURACION!$C$32)-CONFIGURACION!$C$55/($L$2*CONFIGURACION!$C$32)))/CONFIGURACION!$C$12+IF($L$2=1,0,-CONFIGURACION!$C$55/($L$2*CONFIGURACION!$C$32)) -> 15.531635 | K5: ='TABLA PRECIOS'!$L$7+CONFIGURACION!$C$21*('TABLA PRECIOS'!$D$7+CONFIGURACION!$D$32) -> 15.682104 | L5: ='TABLA PRECIOS'!$L$7+CONFIGURACION!$C$21*('TABLA PRECIOS'!$D$7+CONFIGURACION!$D$32)+IF($L$2=1,CONFIGURACION!$C$7/CONFIGURACION!$C$32,-CONFIGURACION!$C$7/($L$2*CONFIGURACION!$C$32)-CONFIGURACION!$C$55/($L$2*CONFIGURACION!$C$32)) -> 17.432104 | M5: =('TABLA PRECIOS'!$L$7+CONFIGURACION!$C$21*('TABLA PRECIOS'!$D$7+CONFIGURACION!$D$32)+IF($L$2=1,CONFIGURACION!$C$7/CONFIGURACION!$C$32,-CONFIGURACION!$C$7/($L$2*CONFIGURACION!$C$32)-CONFIGURACION!$C$55/($L$2*CONFIGURACION!$C$32)))/CONFIGURACION!$C$12+IF($L$2=1,0,-CONFIGURACION!$C$55/($L$2*CONFIGURACION!$C$32)) -> 14.976034 | N5: ='TABLA PRECIOS'!$L$7+CONFIGURACION!$C$22*('TABLA PRECIOS'!$D$7+CONFIGURACION!$D$32) -> 15.682104 | O5: ='TABLA PRECIOS'!$L$7+CONFIGURACION!$C$22*('TABLA PRECIOS'!$D$7+CONFIGURACION!$D$32)+IF($L$2=1,CONFIGURACION!$C$7/CONFIGURACION!$C$32,-CONFIGURACION!$C$7/($L$2*CONFIGURACION!$C$32)-CONFIGURACION!$C$55/($L$2*CONFIGURACION!$C$32)) -> 17.432104 | P5: =('TABLA PRECIOS'!$L$7+CONFIGURACION!$C$22*('TABLA PRECIOS'!$D$7+CONFIGURACION!$D$32)+IF($L$2=1,CONFIGURACION!$C$7/CONFIGURACION!$C$32,-CONFIGURACION!$C$7/($L$2*CONFIGURACION!$C$32)-CONFIGURACION!$C$55/($L$2*CONFIGURACION!$C$32)))/CONFIGURACION!$C$12+IF($L$2=1,0,-CONFIGURACION!$C$55/($L$2*CONFIGURACION!$C$32)) -> 14.976034 | Q5: ='TABLA PRECIOS'!$L$7+CONFIGURACION!$C$23*('TABLA PRECIOS'!$D$7+CONFIGURACION!$D$32) -> 16.070135 | R5: ='TABLA PRECIOS'!$L$7+CONFIGURACION!$C$23*('TABLA PRECIOS'!$D$7+CONFIGURACION!$D$32)+IF($L$2=1,CONFIGURACION!$C$7/CONFIGURACION!$C$32,-CONFIGURACION!$C$7/($L$2*CONFIGURACION!$C$32)-CONFIGURACION!$C$55/($L$2*CONFIGURACION!$C$32)) -> 17.820135 | S5: =('TABLA PRECIOS'!$L$7+CONFIGURACION!$C$23*('TABLA PRECIOS'!$D$7+CONFIGURACION!$D$32)+IF($L$2=1,CONFIGURACION!$C$7/CONFIGURACION!$C$32,-CONFIGURACION!$C$7/($L$2*CONFIGURACION!$C$32)-CONFIGURACION!$C$55/($L$2*CONFIGURACION!$C$32)))/CONFIGURACION!$C$12+IF($L$2=1,0,-CONFIGURACION!$C$55/($L$2*CONFIGURACION!$C$32)) -> 15.309395 | T5: ='TABLA PRECIOS'!$L$7+CONFIGURACION!$C$24*('TABLA PRECIOS'!$D$7+CONFIGURACION!$D$32) -> 20.079791 | U5: ='TABLA PRECIOS'!$L$7+CONFIGURACION!$C$24*('TABLA PRECIOS'!$D$7+CONFIGURACION!$D$32)+IF($L$2=1,CONFIGURACION!$C$7/CONFIGURACION!$C$32,-CONFIGURACION!$C$7/($L$2*CONFIGURACION!$C$32)-CONFIGURACION!$C$55/($L$2*CONFIGURACION!$C$32)) -> 21.829791 | V5: =('TABLA PRECIOS'!$L$7+CONFIGURACION!$C$24*('TABLA PRECIOS'!$D$7+CONFIGURACION!$D$32)+IF($L$2=1,CONFIGURACION!$C$7/CONFIGURACION!$C$32,-CONFIGURACION!$C$7/($L$2*CONFIGURACION!$C$32)-CONFIGURACION!$C$55/($L$2*CONFIGURACION!$C$32)))/CONFIGURACION!$C$12+IF($L$2=1,0,-CONFIGURACION!$C$55/($L$2*CONFIGURACION!$C$32)) -> 18.754116 | W5: ='TABLA PRECIOS'!$L$7+CONFIGURACION!$C$25*('TABLA PRECIOS'!$D$7+CONFIGURACION!$D$32) -> 16.328823 | X5: ='TABLA PRECIOS'!$L$7+CONFIGURACION!$C$25*('TABLA PRECIOS'!$D$7+CONFIGURACION!$D$32)+IF($L$2=1,CONFIGURACION!$C$7/CONFIGURACION!$C$32,-CONFIGURACION!$C$7/($L$2*CONFIGURACION!$C$32)-CONFIGURACION!$C$55/($L$2*CONFIGURACION!$C$32)) -> 18.078823 | Y5: =('TABLA PRECIOS'!$L$7+CONFIGURACION!$C$25*('TABLA PRECIOS'!$D$7+CONFIGURACION!$D$32)+IF($L$2=1,CONFIGURACION!$C$7/CONFIGURACION!$C$32,-CONFIGURACION!$C$7/($L$2*CONFIGURACION!$C$32)-CONFIGURACION!$C$55/($L$2*CONFIGURACION!$C$32)))/CONFIGURACION!$C$12+IF($L$2=1,0,-CONFIGURACION!$C$55/($L$2*CONFIGURACION!$C$32)) -> 15.531635 | Z5: ='TABLA PRECIOS'!$L$7+CONFIGURACION!$C$26*('TABLA PRECIOS'!$D$7+CONFIGURACION!$D$32) -> 11.931135 | AA5: ='TABLA PRECIOS'!$L$7+CONFIGURACION!$C$26*('TABLA PRECIOS'!$D$7+CONFIGURACION!$D$32)+IF($L$2=1,CONFIGURACION!$C$7/CONFIGURACION!$C$32,-CONFIGURACION!$C$7/($L$2*CONFIGURACION!$C$32)-CONFIGURACION!$C$55/($L$2*CONFIGURACION!$C$32)) -> 13.681135 | AB5: =('TABLA PRECIOS'!$L$7+CONFIGURACION!$C$26*('TABLA PRECIOS'!$D$7+CONFIGURACION!$D$32)+IF($L$2=1,CONFIGURACION!$C$7/CONFIGURACION!$C$32,-CONFIGURACION!$C$7/($L$2*CONFIGURACION!$C$32)-CONFIGURACION!$C$55/($L$2*CONFIGURACION!$C$32)))/CONFIGURACION!$C$12+IF($L$2=1,0,-CONFIGURACION!$C$55/($L$2*CONFIGURACION!$C$32)) -> 11.753553 | AC5: ='TABLA PRECIOS'!$L$7+CONFIGURACION!$C$27*('TABLA PRECIOS'!$D$7+CONFIGURACION!$D$32) -> 14.388666 | AD5: ='TABLA PRECIOS'!$L$7+CONFIGURACION!$C$27*('TABLA PRECIOS'!$D$7+CONFIGURACION!$D$32)+IF($L$2=1,CONFIGURACION!$C$7/CONFIGURACION!$C$32,-CONFIGURACION!$C$7/($L$2*CONFIGURACION!$C$32)-CONFIGURACION!$C$55/($L$2*CONFIGURACION!$C$32)) -> 16.138666 | AE5: =('TABLA PRECIOS'!$L$7+CONFIGURACION!$C$27*('TABLA PRECIOS'!$D$7+CONFIGURACION!$D$32)+IF($L$2=1,CONFIGURACION!$C$7/CONFIGURACION!$C$32,-CONFIGURACION!$C$7/($L$2*CONFIGURACION!$C$32)-CONFIGURACION!$C$55/($L$2*CONFIGURACION!$C$32)))/CONFIGURACION!$C$12+IF($L$2=1,0,-CONFIGURACION!$C$55/($L$2*CONFIGURACION!$C$32)) -> 13.864834
B6: F-PN016 | C6: Lulo | D6: 2.5 | E6: ='TABLA PRECIOS'!$L$8+CONFIGURACION!$C$19*('TABLA PRECIOS'!$D$8+CONFIGURACION!$D$34) -> 14.583 | F6: ='TABLA PRECIOS'!$L$8+CONFIGURACION!$C$19*('TABLA PRECIOS'!$D$8+CONFIGURACION!$D$34)+IF($L$2=1,CONFIGURACION!$C$7/CONFIGURACION!$C$34,-CONFIGURACION!$C$7/($L$2*CONFIGURACION!$C$34)-CONFIGURACION!$C$55/($L$2*CONFIGURACION!$C$34)) -> 16.333 | G6: =('TABLA PRECIOS'!$L$8+CONFIGURACION!$C$19*('TABLA PRECIOS'!$D$8+CONFIGURACION!$D$34)+IF($L$2=1,CONFIGURACION!$C$7/CONFIGURACION!$C$34,-CONFIGURACION!$C$7/($L$2*CONFIGURACION!$C$34)-CONFIGURACION!$C$55/($L$2*CONFIGURACION!$C$34)))/CONFIGURACION!$C$12+IF($L$2=1,0,-CONFIGURACION!$C$55/($L$2*CONFIGURACION!$C$34)) -> 14.031787 | H6: ='TABLA PRECIOS'!$L$8+CONFIGURACION!$C$20*('TABLA PRECIOS'!$D$8+CONFIGURACION!$D$34) -> 16.126438 | I6: ='TABLA PRECIOS'!$L$8+CONFIGURACION!$C$20*('TABLA PRECIOS'!$D$8+CONFIGURACION!$D$34)+IF($L$2=1,CONFIGURACION!$C$7/CONFIGURACION!$C$34,-CONFIGURACION!$C$7/($L$2*CONFIGURACION!$C$34)-CONFIGURACION!$C$55/($L$2*CONFIGURACION!$C$34)) -> 17.876438 | J6: =('TABLA PRECIOS'!$L$8+CONFIGURACION!$C$20*('TABLA PRECIOS'!$D$8+CONFIGURACION!$D$34)+IF($L$2=1,CONFIGURACION!$C$7/CONFIGURACION!$C$34,-CONFIGURACION!$C$7/($L$2*CONFIGURACION!$C$34)-CONFIGURACION!$C$55/($L$2*CONFIGURACION!$C$34)))/CONFIGURACION!$C$12+IF($L$2=1,0,-CONFIGURACION!$C$55/($L$2*CONFIGURACION!$C$34)) -> 15.357764 | K6: ='TABLA PRECIOS'!$L$8+CONFIGURACION!$C$21*('TABLA PRECIOS'!$D$8+CONFIGURACION!$D$34) -> 15.354719 | L6: ='TABLA PRECIOS'!$L$8+CONFIGURACION!$C$21*('TABLA PRECIOS'!$D$8+CONFIGURACION!$D$34)+IF($L$2=1,CONFIGURACION!$C$7/CONFIGURACION!$C$34,-CONFIGURACION!$C$7/($L$2*CONFIGURACION!$C$34)-CONFIGURACION!$C$55/($L$2*CONFIGURACION!$C$34)) -> 17.104719 | M6: =('TABLA PRECIOS'!$L$8+CONFIGURACION!$C$21*('TABLA PRECIOS'!$D$8+CONFIGURACION!$D$34)+IF($L$2=1,CONFIGURACION!$C$7/CONFIGURACION!$C$34,-CONFIGURACION!$C$7/($L$2*CONFIGURACION!$C$34)-CONFIGURACION!$C$55/($L$2*CONFIGURACION!$C$34)))/CONFIGURACION!$C$12+IF($L$2=1,0,-CONFIGURACION!$C$55/($L$2*CONFIGURACION!$C$34)) -> 14.694776 | N6: ='TABLA PRECIOS'!$L$8+CONFIGURACION!$C$22*('TABLA PRECIOS'!$D$8+CONFIGURACION!$D$34) -> 15.354719 | O6: ='TABLA PRECIOS'!$L$8+CONFIGURACION!$C$22*('TABLA PRECIOS'!$D$8+CONFIGURACION!$D$34)+IF($L$2=1,CONFIGURACION!$C$7/CONFIGURACION!$C$34,-CONFIGURACION!$C$7/($L$2*CONFIGURACION!$C$34)-CONFIGURACION!$C$55/($L$2*CONFIGURACION!$C$34)) -> 17.104719 | P6: =('TABLA PRECIOS'!$L$8+CONFIGURACION!$C$22*('TABLA PRECIOS'!$D$8+CONFIGURACION!$D$34)+IF($L$2=1,CONFIGURACION!$C$7/CONFIGURACION!$C$34,-CONFIGURACION!$C$7/($L$2*CONFIGURACION!$C$34)-CONFIGURACION!$C$55/($L$2*CONFIGURACION!$C$34)))/CONFIGURACION!$C$12+IF($L$2=1,0,-CONFIGURACION!$C$55/($L$2*CONFIGURACION!$C$34)) -> 14.694776 | Q6: ='TABLA PRECIOS'!$L$8+CONFIGURACION!$C$23*('TABLA PRECIOS'!$D$8+CONFIGURACION!$D$34) -> 15.81775 | R6: ='TABLA PRECIOS'!$L$8+CONFIGURACION!$C$23*('TABLA PRECIOS'!$D$8+CONFIGURACION!$D$34)+IF($L$2=1,CONFIGURACION!$C$7/CONFIGURACION!$C$34,-CONFIGURACION!$C$7/($L$2*CONFIGURACION!$C$34)-CONFIGURACION!$C$55/($L$2*CONFIGURACION!$C$34)) -> 17.56775 | S6: =('TABLA PRECIOS'!$L$8+CONFIGURACION!$C$23*('TABLA PRECIOS'!$D$8+CONFIGURACION!$D$34)+IF($L$2=1,CONFIGURACION!$C$7/CONFIGURACION!$C$34,-CONFIGURACION!$C$7/($L$2*CONFIGURACION!$C$34)-CONFIGURACION!$C$55/($L$2*CONFIGURACION!$C$34)))/CONFIGURACION!$C$12+IF($L$2=1,0,-CONFIGURACION!$C$55/($L$2*CONFIGURACION!$C$34)) -> 15.092569 | T6: ='TABLA PRECIOS'!$L$8+CONFIGURACION!$C$24*('TABLA PRECIOS'!$D$8+CONFIGURACION!$D$34) -> 20.602406 | U6: ='TABLA PRECIOS'!$L$8+CONFIGURACION!$C$24*('TABLA PRECIOS'!$D$8+CONFIGURACION!$D$34)+IF($L$2=1,CONFIGURACION!$C$7/CONFIGURACION!$C$34,-CONFIGURACION!$C$7/($L$2*CONFIGURACION!$C$34)-CONFIGURACION!$C$55/($L$2*CONFIGURACION!$C$34)) -> 22.352406 | V6: =('TABLA PRECIOS'!$L$8+CONFIGURACION!$C$24*('TABLA PRECIOS'!$D$8+CONFIGURACION!$D$34)+IF($L$2=1,CONFIGURACION!$C$7/CONFIGURACION!$C$34,-CONFIGURACION!$C$7/($L$2*CONFIGURACION!$C$34)-CONFIGURACION!$C$55/($L$2*CONFIGURACION!$C$34)))/CONFIGURACION!$C$12+IF($L$2=1,0,-CONFIGURACION!$C$55/($L$2*CONFIGURACION!$C$34)) -> 19.203098 | W6: ='TABLA PRECIOS'!$L$8+CONFIGURACION!$C$25*('TABLA PRECIOS'!$D$8+CONFIGURACION!$D$34) -> 16.126438 | X6: ='TABLA PRECIOS'!$L$8+CONFIGURACION!$C$25*('TABLA PRECIOS'!$D$8+CONFIGURACION!$D$34)+IF($L$2=1,CONFIGURACION!$C$7/CONFIGURACION!$C$34,-CONFIGURACION!$C$7/($L$2*CONFIGURACION!$C$34)-CONFIGURACION!$C$55/($L$2*CONFIGURACION!$C$34)) -> 17.876438 | Y6: =('TABLA PRECIOS'!$L$8+CONFIGURACION!$C$25*('TABLA PRECIOS'!$D$8+CONFIGURACION!$D$34)+IF($L$2=1,CONFIGURACION!$C$7/CONFIGURACION!$C$34,-CONFIGURACION!$C$7/($L$2*CONFIGURACION!$C$34)-CONFIGURACION!$C$55/($L$2*CONFIGURACION!$C$34)))/CONFIGURACION!$C$12+IF($L$2=1,0,-CONFIGURACION!$C$55/($L$2*CONFIGURACION!$C$34)) -> 15.357764 | Z6: ='TABLA PRECIOS'!$L$8+CONFIGURACION!$C$26*('TABLA PRECIOS'!$D$8+CONFIGURACION!$D$34) -> 10.87875 | AA6: ='TABLA PRECIOS'!$L$8+CONFIGURACION!$C$26*('TABLA PRECIOS'!$D$8+CONFIGURACION!$D$34)+IF($L$2=1,CONFIGURACION!$C$7/CONFIGURACION!$C$34,-CONFIGURACION!$C$7/($L$2*CONFIGURACION!$C$34)-CONFIGURACION!$C$55/($L$2*CONFIGURACION!$C$34)) -> 12.62875 | AB6: =('TABLA PRECIOS'!$L$8+CONFIGURACION!$C$26*('TABLA PRECIOS'!$D$8+CONFIGURACION!$D$34)+IF($L$2=1,CONFIGURACION!$C$7/CONFIGURACION!$C$34,-CONFIGURACION!$C$7/($L$2*CONFIGURACION!$C$34)-CONFIGURACION!$C$55/($L$2*CONFIGURACION!$C$34)))/CONFIGURACION!$C$12+IF($L$2=1,0,-CONFIGURACION!$C$55/($L$2*CONFIGURACION!$C$34)) -> 10.849442 | AC6: ='TABLA PRECIOS'!$L$8+CONFIGURACION!$C$27*('TABLA PRECIOS'!$D$8+CONFIGURACION!$D$34) -> 13.811281 | AD6: ='TABLA PRECIOS'!$L$8+CONFIGURACION!$C$27*('TABLA PRECIOS'!$D$8+CONFIGURACION!$D$34)+IF($L$2=1,CONFIGURACION!$C$7/CONFIGURACION!$C$34,-CONFIGURACION!$C$7/($L$2*CONFIGURACION!$C$34)-CONFIGURACION!$C$55/($L$2*CONFIGURACION!$C$34)) -> 15.561281 | AE6: =('TABLA PRECIOS'!$L$8+CONFIGURACION!$C$27*('TABLA PRECIOS'!$D$8+CONFIGURACION!$D$34)+IF($L$2=1,CONFIGURACION!$C$7/CONFIGURACION!$C$34,-CONFIGURACION!$C$7/($L$2*CONFIGURACION!$C$34)-CONFIGURACION!$C$55/($L$2*CONFIGURACION!$C$34)))/CONFIGURACION!$C$12+IF($L$2=1,0,-CONFIGURACION!$C$55/($L$2*CONFIGURACION!$C$34)) -> 13.368799
